Workbook
Name FP: Results!$C$4
Name FP0: Results!$D$4
Name TP: Results!$B$4

Sheet Ratings
A1: doc_id | B1: doc_title | C1: doc_group | D1: label_id | E1: gold | F1: suggested | G1: qm_ratings | H1: llm_relevance | I1: cosine_similarity | J1: label_text | K1: term | L1: candidate | M1: 0 | N1: Rating | O1: mapping_related_error | P1: True Positives | Q1: False Positives | R1: False Negatives | S1: FP0 | T1: FP1 | U1: FP2 | V1: FNM | W1: FNC | X1: MEU | Y1: MEA
A2: 3A1645658597 | B2: Handbuch des Deutschen in West- und Mitteleuropa : Sprachminderheiten und Mehrsprachigkeitskonstellationen | C2: (classificationName=linsearch:mapping)lin | D2: gnd:1212065077 | E2: FALSE | F2: TRUE | G2: NNN | H2: 0.9 | I2: 0.99999138 | J2: Linguistic Landscape | K2: Sprachlandschaft | L2: Sprachlandschaft | M2: =IF(A2<>A1,M1 + 1, M1) -> 1 | N2: FP0 | P2: =IF(AND(E2,F2),1,0) -> 0 | Q2: =IF(AND(NOT(E2),F2),1,0) -> 1 | R2: =IF(AND(E2,NOT(F2)),1,0) -> 0 | S2: =IF($N2="FP0", 1, 0) -> 1 | T2: =IF($N2="FP1", 1, 0) -> 0 | U2: =IF($N2="FP2", 1, 0) -> 0 | V2: =IF($N2="FNM", 1, 0) -> 0 | W2: =IF($N2="FNC", 1, 0) -> 0 | X2: =IF($O2="MEU", 1, 0) -> 0 | Y2: =IF($O2="MEA", 1, 0) -> 0
A3: 3A1645658597 | B3: Handbuch des Deutschen in West- und Mitteleuropa : Sprachminderheiten und Mehrsprachigkeitskonstellationen | C3: (classificationName=linsearch:mapping)lin | D3: gnd:4038403-2 | E3: TRUE | F3: TRUE | G3: YYY | H3: 0.9 | I3: 0.99999143 | J3: Mehrsprachigkeit | K3: Mehrsprachigkeit | L3: Mehrsprachigkeit | M3: =IF(A3<>A2,M2 + 1, M2) -> 1 | N3: TP | P3: =IF(AND(E3,F3),1,0) -> 1 | Q3: =IF(AND(NOT(E3),F3),1,0) -> 0 | R3: =IF(AND(E3,NOT(F3)),1,0) -> 0 | S3: =IF($N3="FP0", 1, 0) -> 0 | T3: =IF($N3="FP1", 1, 0) -> 0 | U3: =IF($N3="FP2", 1, 0) -> 0 | V3: =IF($N3="FNM", 1, 0) -> 0 | W3: =IF($N3="FNC", 1, 0) -> 0 | X3: =IF($O3="MEU", 1, 0) -> 0 | Y3: =IF($O3="MEA", 1, 0) -> 0
A4: 3A1645658597 | B4: Handbuch des Deutschen in West- und Mitteleuropa : Sprachminderheiten und Mehrsprachigkeitskonstellationen | C4: (classificationName=linsearch:mapping)lin | D4: gnd:4113292-0 | E4: TRUE | F4: TRUE | G4: YYY | J4: Deutsch | M4: =IF(A4<>A3,M3 + 1, M3) -> 1 | N4: TP | P4: =IF(AND(E4,F4),1,0) -> 1 | Q4: =IF(AND(NOT(E4),F4),1,0) -> 0 | R4: =IF(AND(E4,NOT(F4)),1,0) -> 0 | S4: =IF($N4="FP0", 1, 0) -> 0 | T4: =IF($N4="FP1", 1, 0) -> 0 | U4: =IF($N4="FP2", 1, 0) -> 0 | V4: =IF($N4="FNM", 1, 0) -> 0 | W4: =IF($N4="FNC", 1, 0) -> 0 | X4: =IF($O4="MEU", 1, 0) -> 0 | Y4: =IF($O4="MEA", 1, 0) -> 0
A5: 3A1645658597 | B5: Handbuch des Deutschen in West- und Mitteleuropa : Sprachminderheiten und Mehrsprachigkeitskonstellationen | C5: (classificationName=linsearch:mapping)lin | D5: gnd:4131504-2 | E5: FALSE | F5: TRUE | G5: YYY | H5: 0.9 | I5: 0.99998866 | J5: Sprachliche Minderheit | K5: Sprachminderheit | L5: Sprachminderheit | M5: =IF(A5<>A4,M4 + 1, M4) -> 1 | N5: FP2 | P5: =IF(AND(E5,F5),1,0) -> 0 | Q5: =IF(AND(NOT(E5),F5),1,0) -> 1 | R5: =IF(AND(E5,NOT(F5)),1,0) -> 0 | S5: =IF($N5="FP0", 1, 0) -> 0 | T5: =IF($N5="FP1", 1, 0) -> 0 | U5: =IF($N5="FP2", 1, 0) -> 1 | V5: =IF($N5="FNM", 1, 0) -> 0 | W5: =IF($N5="FNC", 1, 0) -> 0 | X5: =IF($O5="MEU", 1, 0) -> 0 | Y5: =IF($O5="MEA", 1, 0) -> 0
A6: 3A1645658597 | B6: Handbuch des Deutschen in West- und Mitteleuropa : Sprachminderheiten und Mehrsprachigkeitskonstellationen | C6: (classificationName=linsearch:mapping)lin | D6: gnd:4191506-9 | E6: FALSE | F6: TRUE | G6: NNN | H6: 0.9 | I6: 0.99999049 | J6: Sprachgebrauch | K6: Sprachgebrauch | L6: Sprachgebrauch | M6: =IF(A6<>A5,M5 + 1, M5) -> 1 | N6: FP0 | P6: =IF(AND(E6,F6),1,0) -> 0 | Q6: =IF(AND(NOT(E6),F6),1,0) -> 1 | R6: =IF(AND(E6,NOT(F6)),1,0) -> 0 | S6: =IF($N6="FP0", 1, 0) -> 1 | T6: =IF($N6="FP1", 1, 0) -> 0 | U6: =IF($N6="FP2", 1, 0) -> 0 | V6: =IF($N6="FNM", 1, 0) -> 0 | W6: =IF($N6="FNC", 1, 0) -> 0 | X6: =IF($O6="MEU", 1, 0) -> 0 | Y6: =IF($O6="MEA", 1, 0) -> 0
A7: 3A1645658597 | B7: Handbuch des Deutschen in West- und Mitteleuropa : Sprachminderheiten und Mehrsprachigkeitskonstellationen | C7: (classificationName=linsearch:mapping)lin | D7: gnd:4132313-0 | E7: TRUE | F7: FALSE | J7: Minderheitensprache | M7: =IF(A7<>A6,M6 + 1, M6) -> 1 | N7: FNM | P7: =IF(AND(E7,F7),1,0) -> 0 | Q7: =IF(AND(NOT(E7),F7),1,0) -> 0 | R7: =IF(AND(E7,NOT(F7)),1,0) -> 1 | S7: =IF($N7="FP0", 1, 0) -> 0 | T7: =IF($N7="FP1", 1, 0) -> 0 | U7: =IF($N7="FP2", 1, 0) -> 0 | V7: =IF($N7="FNM", 1, 0) -> 1 | W7: =IF($N7="FNC", 1, 0) -> 0 | X7: =IF($O7="MEU", 1, 0) -> 0 | Y7: =IF($O7="MEA", 1, 0) -> 0
A8: 3A1681233886 | B8: Im Spiegel der Sprache : warum die Welt in anderen Sprachen anders aussieht | C8: (classificationName=linsearch:mapping)lin | D8: gnd:4056449-6 | E8: TRUE | F8: TRUE | G8: YYY | H8: 1 | I8: 0.99999236 | J8: Sprache | K8: Sprache | L8: Sprache | M8: =IF(A8<>A7,M7 + 1, M7) -> 2 | N8: TP | P8: =IF(AND(E8,F8),1,0) -> 1 | Q8: =IF(AND(NOT(E8),F8),1,0) -> 0 | R8: =IF(AND(E8,NOT(F8)),1,0) -> 0 | S8: =IF($N8="FP0", 1, 0) -> 0 | T8: =IF($N8="FP1", 1, 0) -> 0 | U8: =IF($N8="FP2", 1, 0) -> 0 | V8: =IF($N8="FNM", 1, 0) -> 0 | W8: =IF($N8="FNC", 1, 0) -> 0 | X8: =IF($O8="MEU", 1, 0) -> 0 | Y8: =IF($O8="MEA", 1, 0) -> 0
A9: 3A1681233886 | B9: Im Spiegel der Sprache : warum die Welt in anderen Sprachen anders aussieht | C9: (classificationName=linsearch:mapping)lin | D9: gnd:4074250-7 | E9: FALSE | F9: TRUE | G9: III | H9: 1 | I9: 0.9999928 | J9: Linguistik | K9: Linguistik | L9: Linguistik | M9: =IF(A9<>A8,M8 + 1, M8) -> 2 | N9: FP1 | P9: =IF(AND(E9,F9),1,0) -> 0 | Q9: =IF(AND(NOT(E9),F9),1,0) -> 1 | R9: =IF(AND(E9,NOT(F9)),1,0) -> 0 | S9: =IF($N9="FP0", 1, 0) -> 0 | T9: =IF($N9="FP1", 1, 0) -> 1 | U9: =IF($N9="FP2", 1, 0) -> 0 | V9: =IF($N9="FNM", 1, 0) -> 0 | W9: =IF($N9="FNC", 1, 0) -> 0 | X9: =IF($O9="MEU", 1, 0) -> 0 | Y9: =IF($O9="MEA", 1, 0) -> 0
A10: 3A1681233886 | B10: Im Spiegel der Sprache : warum die Welt in anderen Sprachen anders aussieht | C10: (classificationName=linsearch:mapping)lin | D10: gnd:4064317-7 | E10: FALSE | F10: TRUE | G10: NNN | H10: 0.9 | I10: 0.99999029 | J10: Wahrnehmung | K10: Wahrnehmung | L10: Wahrnehmung | M10: =IF(A10<>A9,M9 + 1, M9) -> 2 | N10: FP0 | P10: =IF(AND(E10,F10),1,0) -> 0 | Q10: =IF(AND(NOT(E10),F10),1,0) -> 1 | R10: =IF(AND(E10,NOT(F10)),1,0) -> 0 | S10: =IF($N10="FP0", 1, 0) -> 1 | T10: =IF($N10="FP1", 1, 0) -> 0 | U10: =IF($N10="FP2", 1, 0) -> 0 | V10: =IF($N10="FNM", 1, 0) -> 0 | W10: =IF($N10="FNC", 1, 0) -> 0 | X10: =IF($O10="MEU", 1, 0) -> 0 | Y10: =IF($O10="MEA", 1, 0) -> 0
A11: 3A1681233886 | B11: Im Spiegel der Sprache : warum die Welt in anderen Sprachen anders aussieht | C11: (classificationName=linsearch:mapping)lin | D11: gnd:4125698-0 | E11: TRUE | F11: TRUE | G11: YYY | H11: 0.8 | I11: 0.99999104 | J11: Kultur | K11: Kultur | L11: Kultur | M11: =IF(A11<>A10,M10 + 1, M10) -> 2 | N11: TP | P11: =IF(AND(E11,F11),1,0) -> 1 | Q11: =IF(AND(NOT(E11),F11),1,0) -> 0 | R11: =IF(AND(E11,NOT(F11)),1,0) -> 0 | S11: =IF($N11="FP0", 1, 0) -> 0 | T11: =IF($N11="FP1", 1, 0) -> 0 | U11: =IF($N11="FP2", 1, 0) -> 0 | V11: =IF($N11="FNM", 1, 0) -> 0 | W11: =IF($N11="FNC", 1, 0) -> 0 | X11: =IF($O11="MEU", 1, 0) -> 0 | Y11: =IF($O11="MEA", 1, 0) -> 0
A12: 3A1681233886 | B12: Im Spiegel der Sprache : warum die Welt in anderen Sprachen anders aussieht | C12: (classificationName=linsearch:mapping)lin | D12: gnd:4187739-1 | E12: TRUE | F12: FALSE | J12: Vergleichende Sprachwissenschaft | M12: =IF(A12<>A11,M11 + 1, M11) -> 2 | N12: FNM | P12: =IF(AND(E12,F12),1,0) -> 0 | Q12: =IF(AND(NOT(E12),F12),1,0) -> 0 | R12: =IF(AND(E12,NOT(F12)),1,0) -> 1 | S12: =IF($N12="FP0", 1, 0) -> 0 | T12: =IF($N12="FP1", 1, 0) -> 0 | U12: =IF($N12="FP2", 1, 0) -> 0 | V12: =IF($N12="FNM", 1, 0) -> 1 | W12: =IF($N12="FNC", 1, 0) -> 0 | X12: =IF($O12="MEU", 1, 0) -> 0 | Y12: =IF($O12="MEA", 1, 0) -> 0
A13: 3A1681233886 | B13: Im Spiegel der Sprache : warum die Welt in anderen Sprachen anders aussieht | C13: (classificationName=linsearch:mapping)lin | D13: gnd:4114570-7 | E13: TRUE | F13: FALSE | J13: Mentalität | M13: =IF(A13<>A12,M12 + 1, M12) -> 2 | N13: FNM | P13: =IF(AND(E13,F13),1,0) -> 0 | Q13: =IF(AND(NOT(E13),F13),1,0) -> 0 | R13: =IF(AND(E13,NOT(F13)),1,0) -> 1 | S13: =IF($N13="FP0", 1, 0) -> 0 | T13: =IF($N13="FP1", 1, 0) -> 0 | U13: =IF($N13="FP2", 1, 0) -> 0 | V13: =IF($N13="FNM", 1, 0) -> 1 | W13: =IF($N13="FNC", 1, 0) -> 0 | X13: =IF($O13="MEU", 1, 0) -> 0 | Y13: =IF($O13="MEA", 1, 0) -> 0
A14: 3A1728461472 | B14: Die Syntax des Semikolons : von links ein Punkt – nach rechts ein Komma | C14: (classificationName=linsearch:mapping)lin | D14: gnd:4058779-4 | E14: FALSE | F14: TRUE | G14: YYY | H14: 1 | I14: 0.99998304 | J14: Syntax | K14: Syntax | L14: Syntax | M14: =IF(A14<>A13,M13 + 1, M13) -> 3 | N14: FP2 | P14: =IF(AND(E14,F14),1,0) -> 0 | Q14: =IF(AND(NOT(E14),F14),1,0) -> 1 | R14: =IF(AND(E14,NOT(F14)),1,0) -> 0 | S14: =IF($N14="FP0", 1, 0) -> 0 | T14: =IF($N14="FP1", 1, 0) -> 0 | U14: =IF($N14="FP2", 1, 0) -> 1 | V14: =IF($N14="FNM", 1, 0) -> 0 | W14: =IF($N14="FNC", 1, 0) -> 0 | X14: =IF($O14="MEU", 1, 0) -> 0 | Y14: =IF($O14="MEA", 1, 0) -> 0
A15: 3A1728461472 | B15: Die Syntax des Semikolons : von links ein Punkt – nach rechts ein Komma | C15: (classificationName=linsearch:mapping)lin | D15: gnd:4021806-5 | E15: FALSE | F15: TRUE | G15: N | H15: 0.9 | I15: 0.99999173 | J15: Grammatik | K15: Grammatik | L15: Grammatik | M15: =IF(A15<>A14,M14 + 1, M14) -> 3 | N15: FP0 | P15: =IF(AND(E15,F15),1,0) -> 0 | Q15: =IF(AND(NOT(E15),F15),1,0) -> 1 | R15: =IF(AND(E15,NOT(F15)),1,0) -> 0 | S15: =IF($N15="FP0", 1, 0) -> 1 | T15: =IF($N15="FP1", 1, 0) -> 0 | U15: =IF($N15="FP2", 1, 0) -> 0 | V15: =IF($N15="FNM", 1, 0) -> 0 | W15: =IF($N15="FNC", 1, 0) -> 0 | X15: =IF($O15="MEU", 1, 0) -> 0 | Y15: =IF($O15="MEA", 1, 0) -> 0
A16: 3A1728461472 | B16: Die Syntax des Semikolons : von links ein Punkt – nach rechts ein Komma | C16: (classificationName=linsearch:mapping)lin | D16: gnd:4079477-5 | E16: FALSE | F16: TRUE | G16: YYY | H16: 0.9 | I16: 0.99999161 | J16: Zeichensetzung | K16: Interpunktion | L16: Interpunktion | M16: =IF(A16<>A15,M15 + 1, M15) -> 3 | N16: FP2 | P16: =IF(AND(E16,F16),1,0) -> 0 | Q16: =IF(AND(NOT(E16),F16),1,0) -> 1 | R16: =IF(AND(E16,NOT(F16)),1,0) -> 0 | S16: =IF($N16="FP0", 1, 0) -> 0 | T16: =IF($N16="FP1", 1, 0) -> 0 | U16: =IF($N16="FP2", 1, 0) -> 1 | V16: =IF($N16="FNM", 1, 0) -> 0 | W16: =IF($N16="FNC", 1, 0) -> 0 | X16: =IF($O16="MEU", 1, 0) -> 0 | Y16: =IF($O16="MEA", 1, 0) -> 0
A17: 3A1728461472 | B17: Die Syntax des Semikolons : von links ein Punkt – nach rechts ein Komma | C17: (classificationName=linsearch:mapping)lin | D17: gnd:4113292-0 | E17: FALSE | F17: TRUE | G17: YYY | J17: Deutsch | M17: =IF(A17<>A16,M16 + 1, M16) -> 3 | N17: FP2 | P17: =IF(AND(E17,F17),1,0) -> 0 | Q17: =IF(AND(NOT(E17),F17),1,0) -> 1 | R17: =IF(AND(E17,NOT(F17)),1,0) -> 0 | S17: =IF($N17="FP0", 1, 0) -> 0 | T17: =IF($N17="FP1", 1, 0) -> 0 | U17: =IF($N17="FP2", 1, 0) -> 1 | V17: =IF($N17="FNM", 1, 0) -> 0 | W17: =IF($N17="FNC", 1, 0) -> 0 | X17: =IF($O17="MEU", 1, 0) -> 0 | Y17: =IF($O17="MEA", 1, 0) -> 0
A18: 3A1728461472 | B18: Die Syntax des Semikolons : von links ein Punkt – nach rechts ein Komma | C18: (classificationName=linsearch:mapping)lin | D18: gnd:119227699X | E18: TRUE | F18: FALSE | J18: Semikolon | M18: =IF(A18<>A17,M17 + 1, M17) -> 3 | N18: FNM | P18: =IF(AND(E18,F18),1,0) -> 0 | Q18: =IF(AND(NOT(E18),F18),1,0) -> 0 | R18: =IF(AND(E18,NOT(F18)),1,0) -> 1 | S18: =IF($N18="FP0", 1, 0) -> 0 | T18: =IF($N18="FP1", 1, 0) -> 0 | U18: =IF($N18="FP2", 1, 0) -> 0 | V18: =IF($N18="FNM", 1, 0) -> 1 | W18: =IF($N18="FNC", 1, 0) -> 0 | X18: =IF($O18="MEU", 1, 0) -> 0 | Y18: =IF($O18="MEA", 1, 0) -> 0
A19: 3A1760914371 | B19: An exploration of context updating mechanisms from a cross-linguistic perspective | C19: (classificationName=linsearch:mapping)lin | D19: gnd:4076315-8 | E19: TRUE | F19: TRUE | G19: YYY | H19: 0.9 | I19: 0.99998509 | J19: Pragmatik | K19: Pragmatik | L19: Pragmatik | M19: =IF(A19<>A18,M18 + 1, M18) -> 4 | N19: TP | P19: =IF(AND(E19,F19),1,0) -> 1 | Q19: =IF(AND(NOT(E19),F19),1,0) -> 0 | R19: =IF(AND(E19,NOT(F19)),1,0) -> 0 | S19: =IF($N19="FP0", 1, 0) -> 0 | T19: =IF($N19="FP1", 1, 0) -> 0 | U19: =IF($N19="FP2", 1, 0) -> 0 | V19: =IF($N19="FNM", 1, 0) -> 0 | W19: =IF($N19="FNC", 1, 0) -> 0 | X19: =IF($O19="MEU", 1, 0) -> 0 | Y19: =IF($O19="MEA", 1, 0) -> 0
A20: 3A1760914371 | B20: An exploration of context updating mechanisms from a cross-linguistic perspective | C20: (classificationName=linsearch:mapping)lin | D20: gnd:4187739-1 | E20: TRUE | F20: TRUE | G20: YYY | H20: 0.9 | I20: 0.9999902 | J20: Vergleichende Sprachwissenschaft | K20: Vergleichende Sprachwissenschaft | L20: Vergleichende Sprachwissenschaft | M20: =IF(A20<>A19,M19 + 1, M19) -> 4 | N20: TP | P20: =IF(AND(E20,F20),1,0) -> 1 | Q20: =IF(AND(NOT(E20),F20),1,0) -> 0 | R20: =IF(AND(E20,NOT(F20)),1,0) -> 0 | S20: =IF($N20="FP0", 1, 0) -> 0 | T20: =IF($N20="FP1", 1, 0) -> 0 | U20: =IF($N20="FP2", 1, 0) -> 0 | V20: =IF($N20="FNM", 1, 0) -> 0 | W20: =IF($N20="FNC", 1, 0) -> 0 | X20: =IF($O20="MEU", 1, 0) -> 0 | Y20: =IF($O20="MEA", 1, 0) -> 0
A21: 3A1760914371 | B21: An exploration of context updating mechanisms from a cross-linguistic perspective | C21: (classificationName=linsearch:mapping)lin | D21: gnd:4014777-0 | E21: TRUE | F21: TRUE | G21: YYY | H21: 0.8 | I21: 0.99999132 | J21: Englisch | K21: Englisch | L21: Englisch | M21: =IF(A21<>A20,M20 + 1, M20) -> 4 | N21: TP | P21: =IF(AND(E21,F21),1,0) -> 1 | Q21: =IF(AND(NOT(E21),F21),1,0) -> 0 | R21: =IF(AND(E21,NOT(F21)),1,0) -> 0 | S21: =IF($N21="FP0", 1, 0) -> 0 | T21: =IF($N21="FP1", 1, 0) -> 0 | U21: =IF($N21="FP2", 1, 0) -> 0 | V21: =IF($N21="FNM", 1, 0) -> 0 | W21: =IF($N21="FNC", 1, 0) -> 0 | X21: =IF($O21="MEU", 1, 0) -> 0 | Y21: =IF($O21="MEA", 1, 0) -> 0
A22: 3A1760914371 | B22: An exploration of context updating mechanisms from a cross-linguistic perspective | C22: (classificationName=linsearch:mapping)lin | D22: gnd:4077748-0 | E22: TRUE | F22: TRUE | G22: YYY | H22: 0.8 | I22: 0.99999068 | J22: Sprechakttheorie | K22: Sprechakttheorie | L22: Sprechakttheorie | M22: =IF(A22<>A21,M21 + 1, M21) -> 4 | N22: TP | P22: =IF(AND(E22,F22),1,0) -> 1 | Q22: =IF(AND(NOT(E22),F22),1,0) -> 0 | R22: =IF(AND(E22,NOT(F22)),1,0) -> 0 | S22: =IF($N22="FP0", 1, 0) -> 0 | T22: =IF($N22="FP1", 1, 0) -> 0 | U22: =IF($N22="FP2", 1, 0) -> 0 | V22: =IF($N22="FNM", 1, 0) -> 0 | W22: =IF($N22="FNC", 1, 0) -> 0 | X22: =IF($O22="MEU", 1, 0) -> 0 | Y22: =IF($O22="MEA", 1, 0) -> 0
A23: 3A640863299 | B23: Foreign influences on medieval English : [papers presented at the International conference on foreigen influences on Medieval English held in Warsaw on 12-13 december 2009] | C23: (classificationName=linsearch:mapping)lin | D23: gnd:4039676-9 | E23: TRUE | F23: TRUE | G23: YYY | H23: 1 | I23: 0.99998846 | J23: Mittelenglisch | K23: Mittelenglisch | L23: Mittelenglisch | M23: =IF(A23<>A22,M22 + 1, M22) -> 5 | N23: TP | P23: =IF(AND(E23,F23),1,0) -> 1 | Q23: =IF(AND(NOT(E23),F23),1,0) -> 0 | R23: =IF(AND(E23,NOT(F23)),1,0) -> 0 | S23: =IF($N23="FP0", 1, 0) -> 0 | T23: =IF($N23="FP1", 1, 0) -> 0 | U23: =IF($N23="FP2", 1, 0) -> 0 | V23: =IF($N23="FNM", 1, 0) -> 0 | W23: =IF($N23="FNC", 1, 0) -> 0 | X23: =IF($O23="MEU", 1, 0) -> 0 | Y23: =IF($O23="MEA", 1, 0) -> 0
A24: 3A640863299 | B24: Foreign influences on medieval English : [papers presented at the International conference on foreigen influences on Medieval English held in Warsaw on 12-13 december 2009] | C24: (classificationName=linsearch:mapping)lin | D24: gnd:4071461-5 | E24: FALSE | F24: TRUE | G24: N | H24: 0.2 | I24: 0.8960248 | J24: Fremdsprachenlernen | K24: Fremdsprachenlernen | L24: Fremdsprachen | M24: =IF(A24<>A23,M23 + 1, M23) -> 5 | N24: FP0 | O24: MEA | P24: =IF(AND(E24,F24),1,0) -> 0 | Q24: =IF(AND(NOT(E24),F24),1,0) -> 1 | R24: =IF(AND(E24,NOT(F24)),1,0) -> 0 | S24: =IF($N24="FP0", 1, 0) -> 1 | T24: =IF($N24="FP1", 1, 0) -> 0 | U24: =IF($N24="FP2", 1, 0) -> 0 | V24: =IF($N24="FNM", 1, 0) -> 0 | W24: =IF($N24="FNC", 1, 0) -> 0 | X24: =IF($O24="MEU", 1, 0) -> 0 | Y24: =IF($O24="MEA", 1, 0) -> 1
A25: 3A640863299 | B25: Foreign influences on medieval English : [papers presented at the International conference on foreigen influences on Medieval English held in Warsaw on 12-13 december 2009] | C25: (classificationName=linsearch:mapping)lin | D25: gnd:4002009-5 | E25: FALSE | F25: TRUE | G25: N | H25: 0.2 | I25: 0.99999032 | J25: Angelsachsen | K25: Angelsachsen | L25: Angelsachsen | M25: =IF(A25<>A24,M24 + 1, M24) -> 5 | N25: FP0 | P25: =IF(AND(E25,F25),1,0) -> 0 | Q25: =IF(AND(NOT(E25),F25),1,0) -> 1 | R25: =IF(AND(E25,NOT(F25)),1,0) -> 0 | S25: =IF($N25="FP0", 1, 0) -> 1 | T25: =IF($N25="FP1", 1, 0) -> 0 | U25: =IF($N25="FP2", 1, 0) -> 0 | V25: =IF($N25="FNM", 1, 0) -> 0 | W25: =IF($N25="FNC", 1, 0) -> 0 | X25: =IF($O25="MEU", 1, 0) -> 0 | Y25: =IF($O25="MEA", 1, 0) -> 0
A26: 3A640863299 | B26: Foreign influences on medieval English : [papers presented at the International conference on foreigen influences on Medieval English held in Warsaw on 12-13 december 2009] | C26: (classificationName=linsearch:mapping)lin | D26: gnd:4035076-9 | E26: TRUE | F26: FALSE | J26: Lehnwort | M26: =IF(A26<>A25,M25 + 1, M25) -> 5 | N26: FNM | P26: =IF(AND(E26,F26),1,0) -> 0 | Q26: =IF(AND(NOT(E26),F26),1,0) -> 0 | R26: =IF(AND(E26,NOT(F26)),1,0) -> 1 | S26: =IF($N26="FP0", 1, 0) -> 0 | T26: =IF($N26="FP1", 1, 0) -> 0 | U26: =IF($N26="FP2", 1, 0) -> 0 | V26: =IF($N26="FNM", 1, 0) -> 1 | W26: =IF($N26="FNC", 1, 0) -> 0 | X26: =IF($O26="MEU", 1, 0) -> 0 | Y26: =IF($O26="MEA", 1, 0) -> 0
A27: 3A785204539 | B27: Der Wortschatz der Ebla-Texte : morphologische und lexikalische Analyse | C27: (classificationName=linsearch:mapping)lin | D27: gnd:4035549-4 | E27: FALSE | F27: TRUE | G27: N | H27: 1 | I27: 0.99999195 | J27: Lexikon | K27: Lexikon | L27: Lexikon | M27: =IF(A27<>A26,M26 + 1, M26) -> 6 | N27: FP0 | P27: =IF(AND(E27,F27),1,0) -> 0 | Q27: =IF(AND(NOT(E27),F27),1,0) -> 1 | R27: =IF(AND(E27,NOT(F27)),1,0) -> 0 | S27: =IF($N27="FP0", 1, 0) -> 1 | T27: =IF($N27="FP1", 1, 0) -> 0 | U27: =IF($N27="FP2", 1, 0) -> 0 | V27: =IF($N27="FNM", 1, 0) -> 0 | W27: =IF($N27="FNC", 1, 0) -> 0 | X27: =IF($O27="MEU", 1, 0) -> 0 | Y27: =IF($O27="MEA", 1, 0) -> 0
A28: 3A785204539 | B28: Der Wortschatz der Ebla-Texte : morphologische und lexikalische Analyse | C28: (classificationName=linsearch:mapping)lin | D28: gnd:4056449-6 | E28: FALSE | F28: TRUE | G28: III | H28: 1 | I28: 0.99999236 | J28: Sprache | K28: Sprache | L28: Sprache | M28: =IF(A28<>A27,M27 + 1, M27) -> 6 | N28: FP1 | P28: =IF(AND(E28,F28),1,0) -> 0 | Q28: =IF(AND(NOT(E28),F28),1,0) -> 1 | R28: =IF(AND(E28,NOT(F28)),1,0) -> 0 | S28: =IF($N28="FP0", 1, 0) -> 0 | T28: =IF($N28="FP1", 1, 0) -> 1 | U28: =IF($N28="FP2", 1, 0) -> 0 | V28: =IF($N28="FNM", 1, 0) -> 0 | W28: =IF($N28="FNC", 1, 0) -> 0 | X28: =IF($O28="MEU", 1, 0) -> 0 | Y28: =IF($O28="MEA", 1, 0) -> 0
A29: 3A785204539 | B29: Der Wortschatz der Ebla-Texte : morphologische und lexikalische Analyse | C29: (classificationName=linsearch:mapping)lin | D29: gnd:4220613-3 | E29: TRUE | F29: FALSE | J29: Eblaitisch | M29: =IF(A29<>A28,M28 + 1, M28) -> 6 | N29: FNM | P29: =IF(AND(E29,F29),1,0) -> 0 | Q29: =IF(AND(NOT(E29),F29),1,0) -> 0 | R29: =IF(AND(E29,NOT(F29)),1,0) -> 1 | S29: =IF($N29="FP0", 1, 0) -> 0 | T29: =IF($N29="FP1", 1, 0) -> 0 | U29: =IF($N29="FP2", 1, 0) -> 0 | V29: =IF($N29="FNM", 1, 0) -> 1 | W29: =IF($N29="FNC", 1, 0) -> 0 | X29: =IF($O29="MEU", 1, 0) -> 0 | Y29: =IF($O29="MEA", 1, 0) -> 0
A30: 3A785204539 | B30: Der Wortschatz der Ebla-Texte : morphologische und lexikalische Analyse | C30: (classificationName=linsearch:mapping)lin | D30: gnd:4126555-5 | E30: TRUE | F30: FALSE | J30: Wortschatz | M30: =IF(A30<>A29,M29 + 1, M29) -> 6 | N30: FNM | P30: =IF(AND(E30,F30),1,0) -> 0 | Q30: =IF(AND(NOT(E30),F30),1,0) -> 0 | R30: =IF(AND(E30,NOT(F30)),1,0) -> 1 | S30: =IF($N30="FP0", 1, 0) -> 0 | T30: =IF($N30="FP1", 1, 0) -> 0 | U30: =IF($N30="FP2", 1, 0) -> 0 | V30: =IF($N30="FNM", 1, 0) -> 1 | W30: =IF($N30="FNC", 1, 0) -> 0 | X30: =IF($O30="MEU", 1, 0) -> 0 | Y30: =IF($O30="MEA", 1, 0) -> 0
A31: 3A785204539 | B31: Der Wortschatz der Ebla-Texte : morphologische und lexikalische Analyse | C31: (classificationName=linsearch:mapping)lin | D31: gnd:4040289-7 | E31: TRUE | F31: FALSE | J31: Morphologie | M31: =IF(A31<>A30,M30 + 1, M30) -> 6 | N31: FNM | P31: =IF(AND(E31,F31),1,0) -> 0 | Q31: =IF(AND(NOT(E31),F31),1,0) -> 0 | R31: =IF(AND(E31,NOT(F31)),1,0) -> 1 | S31: =IF($N31="FP0", 1, 0) -> 0 | T31: =IF($N31="FP1", 1, 0) -> 0 | U31: =IF($N31="FP2", 1, 0) -> 0 | V31: =IF($N31="FNM", 1, 0) -> 1 | W31: =IF($N31="FNC", 1, 0) -> 0 | X31: =IF($O31="MEU", 1, 0) -> 0 | Y31: =IF($O31="MEA", 1, 0) -> 0
A32: 3A792504461 | B32: Structural and sociolinguistic perspectives on indigenisation : on multilingualism and language evolution | C32: (classificationName=linsearch:mapping)lin | D32: gnd:4038403-2 | E32: TRUE | F32: TRUE | G32: YYY | H32: 0.9 | I32: 0.99999143 | J32: Mehrsprachigkeit | K32: Mehrsprachigkeit | L32: Mehrsprachigkeit | M32: =IF(A32<>A31,M31 + 1, M31) -> 7 | N32: TP | P32: =IF(AND(E32,F32),1,0) -> 1 | Q32: =IF(AND(NOT(E32),F32),1,0) -> 0 | R32: =IF(AND(E32,NOT(F32)),1,0) -> 0 | S32: =IF($N32="FP0", 1, 0) -> 0 | T32: =IF($N32="FP1", 1, 0) -> 0 | U32: =IF($N32="FP2", 1, 0) -> 0 | V32: =IF($N32="FNM", 1, 0) -> 0 | W32: =IF($N32="FNC", 1, 0) -> 0 | X32: =IF($O32="MEU", 1, 0) -> 0 | Y32: =IF($O32="MEA", 1, 0) -> 0
A33: 3A792504461 | B33: Structural and sociolinguistic perspectives on indigenisation : on multilingualism and language evolution | C33: (classificationName=linsearch:mapping)lin | D33: gnd:4073624-6 | E33: FALSE | F33: TRUE | G33: III | H33: 0.9 | I33: 0.99998915 | J33: Kolonialismus | K33: Kolonialismus | L33: Kolonialismus | M33: =IF(A33<>A32,M32 + 1, M32) -> 7 | N33: FP1 | P33: =IF(AND(E33,F33),1,0) -> 0 | Q33: =IF(AND(NOT(E33),F33),1,0) -> 1 | R33: =IF(AND(E33,NOT(F33)),1,0) -> 0 | S33: =IF($N33="FP0", 1, 0) -> 0 | T33: =IF($N33="FP1", 1, 0) -> 1 | U33: =IF($N33="FP2", 1, 0) -> 0 | V33: =IF($N33="FNM", 1, 0) -> 0 | W33: =IF($N33="FNC", 1, 0) -> 0 | X33: =IF($O33="MEU", 1, 0) -> 0 | Y33: =IF($O33="MEA", 1, 0) -> 0
A34: 3A792504461 | B34: Structural and sociolinguistic perspectives on indigenisation : on multilingualism and language evolution | C34: (classificationName=linsearch:mapping)lin | D34: gnd:4056508-7 | E34: FALSE | F34: TRUE | G34: III | H34: 0.9 | I34: 0.99999147 | J34: Sprachwandel | K34: Sprachwandel | L34: Sprachwandel | M34: =IF(A34<>A33,M33 + 1, M33) -> 7 | N34: FP1 | P34: =IF(AND(E34,F34),1,0) -> 0 | Q34: =IF(AND(NOT(E34),F34),1,0) -> 1 | R34: =IF(AND(E34,NOT(F34)),1,0) -> 0 | S34: =IF($N34="FP0", 1, 0) -> 0 | T34: =IF($N34="FP1", 1, 0) -> 1 | U34: =IF($N34="FP2", 1, 0) -> 0 | V34: =IF($N34="FNM", 1, 0) -> 0 | W34: =IF($N34="FNC", 1, 0) -> 0 | X34: =IF($O34="MEU", 1, 0) -> 0 | Y34: =IF($O34="MEA", 1, 0) -> 0
A35: 3A792504461 | B35: Structural and sociolinguistic perspectives on indigenisation : on multilingualism and language evolution | C35: (classificationName=linsearch:mapping)lin | D35: gnd:4127662-0 | E35: FALSE | F35: TRUE | G35: NNN | H35: 0.8 | I35: 0.78971162 | J35: Indigenismus | K35: Indigenismus | L35: Indigenisierung | M35: =IF(A35<>A34,M34 + 1, M34) -> 7 | N35: FP0 | O35: MEU | P35: =IF(AND(E35,F35),1,0) -> 0 | Q35: =IF(AND(NOT(E35),F35),1,0) -> 1 | R35: =IF(AND(E35,NOT(F35)),1,0) -> 0 | S35: =IF($N35="FP0", 1, 0) -> 1 | T35: =IF($N35="FP1", 1, 0) -> 0 | U35: =IF($N35="FP2", 1, 0) -> 0 | V35: =IF($N35="FNM", 1, 0) -> 0 | W35: =IF($N35="FNC", 1, 0) -> 0 | X35: =IF($O35="MEU", 1, 0) -> 1 | Y35: =IF($O35="MEA", 1, 0) -> 0
A36: 3A792504461 | B36: Structural and sociolinguistic perspectives on indigenisation : on multilingualism and language evolution | C36: (classificationName=linsearch:mapping)lin | D36: gnd:4014777-0 | E36: TRUE | F36: FALSE | J36: Englisch | M36: =IF(A36<>A35,M35 + 1, M35) -> 7 | N36: FNM | P36: =IF(AND(E36,F36),1,0) -> 0 | Q36: =IF(AND(NOT(E36),F36),1,0) -> 0 | R36: =IF(AND(E36,NOT(F36)),1,0) -> 1 | S36: =IF($N36="FP0", 1, 0) -> 0 | T36: =IF($N36="FP1", 1, 0) -> 0 | U36: =IF($N36="FP2", 1, 0) -> 0 | V36: =IF($N36="FNM", 1, 0) -> 1 | W36: =IF($N36="FNC", 1, 0) -> 0 | X36: =IF($O36="MEU", 1, 0) -> 0 | Y36: =IF($O36="MEA", 1, 0) -> 0
A37: 3A792504461 | B37: Structural and sociolinguistic perspectives on indigenisation : on multilingualism and language evolution | C37: (classificationName=linsearch:mapping)lin | D37: gnd:4113615-9 | E37: TRUE | F37: FALSE | J37: Französisch | M37: =IF(A37<>A36,M36 + 1, M36) -> 7 | N37: FNM | P37: =IF(AND(E37,F37),1,0) -> 0 | Q37: =IF(AND(NOT(E37),F37),1,0) -> 0 | R37: =IF(AND(E37,NOT(F37)),1,0) -> 1 | S37: =IF($N37="FP0", 1, 0) -> 0 | T37: =IF($N37="FP1", 1, 0) -> 0 | U37: =IF($N37="FP2", 1, 0) -> 0 | V37: =IF($N37="FNM", 1, 0) -> 1 | W37: =IF($N37="FNC", 1, 0) -> 0 | X37: =IF($O37="MEU", 1, 0) -> 0 | Y37: =IF($O37="MEA", 1, 0) -> 0
A38: 3A828081131 | B38: The function and use of TO and OF in multi-word units | C38: (classificationName=linsearch:mapping)lin | D38: gnd:4014777-0 | E38: TRUE | F38: TRUE | G38: YYY | H38: 0.9 | I38: 0.99999132 | J38: Englisch | K38: Englisch | L38: Englisch | M38: =IF(A38<>A37,M37 + 1, M37) -> 8 | N38: TP | P38: =IF(AND(E38,F38),1,0) -> 1 | Q38: =IF(AND(NOT(E38),F38),1,0) -> 0 | R38: =IF(AND(E38,NOT(F38)),1,0) -> 0 | S38: =IF($N38="FP0", 1, 0) -> 0 | T38: =IF($N38="FP1", 1, 0) -> 0 | U38: =IF($N38="FP2", 1, 0) -> 0 | V38: =IF($N38="FNM", 1, 0) -> 0 | W38: =IF($N38="FNC", 1, 0) -> 0 | X38: =IF($O38="MEU", 1, 0) -> 0 | Y38: =IF($O38="MEA", 1, 0) -> 0
A39: 3A828081131 | B39: The function and use of TO and OF in multi-word units | C39: (classificationName=linsearch:mapping)lin | D39: gnd:4165338-5 | E39: FALSE | F39: TRUE | G39: YYY | H39: 0.9 | I39: 0.99998736 | J39: Korpus Linguistik | K39: Korpus (Linguistik) | L39: Korpus (Linguistik) | M39: =IF(A39<>A38,M38 + 1, M38) -> 8 | N39: FP2 | P39: =IF(AND(E39,F39),1,0) -> 0 | Q39: =IF(AND(NOT(E39),F39),1,0) -> 1 | R39: =IF(AND(E39,NOT(F39)),1,0) -> 0 | S39: =IF($N39="FP0", 1, 0) -> 0 | T39: =IF($N39="FP1", 1, 0) -> 0 | U39: =IF($N39="FP2", 1, 0) -> 1 | V39: =IF($N39="FNM", 1, 0) -> 0 | W39: =IF($N39="FNC", 1, 0) -> 0 | X39: =IF($O39="MEU", 1, 0) -> 0 | Y39: =IF($O39="MEA", 1, 0) -> 0
A40: 3A828081131 | B40: The function and use of TO and OF in multi-word units | C40: (classificationName=linsearch:mapping)lin | D40: gnd:4047008-8 | E40: TRUE | F40: TRUE | G40: YYY | H40: 0.8 | I40: 0.96427577 | J40: Präposition | K40: Präposition | L40: Preposition | M40: =IF(A40<>A39,M39 + 1, M39) -> 8 | N40: TP | P40: =IF(AND(E40,F40),1,0) -> 1 | Q40: =IF(AND(NOT(E40),F40),1,0) -> 0 | R40: =IF(AND(E40,NOT(F40)),1,0) -> 0 | S40: =IF($N40="FP0", 1, 0) -> 0 | T40: =IF($N40="FP1", 1, 0) -> 0 | U40: =IF($N40="FP2", 1, 0) -> 0 | V40: =IF($N40="FNM", 1, 0) -> 0 | W40: =IF($N40="FNC", 1, 0) -> 0 | X40: =IF($O40="MEU", 1, 0) -> 0 | Y40: =IF($O40="MEA", 1, 0) -> 0
...

Sheet Legend
A1: Error-Categories
A2: False Positives
A3: FP0 | B3: just wrong
B4: MEU | C4: Mapping Error, Concept unkown in the GND
B5: MEA | C5: ambiguity in the GND
A6: FP1 | B6: FP, too general
A7: FP2 | B7: FP, yet relevant
A8: False Negatives
A9: FNC | B9: False Negative, but closely matched by other aspect
A10: FNM | B10: False Negative, totally missed
A11: OOV | B11: Unfair FN, out of vocab for shared task
A13: True Positive
A14: TP | B14: when the system suggested precisely the subject term that was annotated in the gold standard
A16: Table Columns
A17: doc_id | B17: Record Identifier in the TIBKAT Collection
A18: label_id | B18: Identifier of a GND subject term
A19: gold | B19: was the label part of gold standard
A20: suggested | B20: was the label suggested by the system
A21: llm_relevance | B21: LLM produced relevance rating in the Rank stage
A22: cosine_similarity | B22: Cosine similarity between columns term and candidate, accorduing to BGE-3 embedding model
A23: label_text | B23: preferred label of a GND subject term
A24: term | B24: preferred or alternate label of a GND subject term, that a candidate was mapped tp
A25: error_categories | B25: as explaioned above
A26: #

Sheet Results
B2: True Positives | C2: False Positives | G2: False Negatives
A3: Category | B3: TP | C3: FP | D3: FP0 | E3: FP1 | F3: FP2 | G3: FN | H3: FNM | I3: FNC
A4: Count | B4: =SUM(Ratings!P2:'Ratings'!P273) -> 66 | C4: =SUM(Ratings!Q2:'Ratings'!Q273) -> 110 | D4: =SUM(Ratings!S2:'Ratings'!S273) -> 43 | E4: =SUM(Ratings!T2:'Ratings'!T273) -> 27 | F4: =SUM(Ratings!U2:'Ratings'!U273) -> 40 | G4: =SUM(Ratings!R2:'Ratings'!R273) -> 96 | H4: =SUM(Ratings!V2:'Ratings'!V273) -> 68 | I4: =SUM(Ratings!W2:'Ratings'!W273) -> 28
C5: =FP/(FP + TP) -> 0.625 | D5: =FP0/FP -> 0.39090909
C6: Sub-Categories of FP0
C7: MEA | D7: =SUM(Ratings!Y2:'Ratings'!Y273) -> 5
C8: MEU | D8: =SUM(Ratings!X2:'Ratings'!X273) -> 11
